<?xml version="1.0" ?>
<sdf version="1.6">
  <model name="prius_hybrid">
    <pose>0 0 0.03 0 0 0</pose>
    <link name="chassis">
      <inertial>
        <mass>1326.0</mass>
        <pose>0 -0.266 0.48 0 0 0</pose>
        <inertia>
          <ixx>2581.13354740</ixx>
          <ixy>0.0</ixy>
          <iyy>591.30846112</iyy>
          <ixz>0.0</ixz>
          <iyz>0.0</iyz>
          <izz>2681.95008628</izz>
        </inertia>
      </inertial>

      <visual name="chassis_visual">
        <geometry>
          <mesh>
            <uri>model://prius_hybrid/meshes/Hybrid.obj</uri>
            <scale>0.01 0.01 0.01</scale>
            <submesh>
              <name>Hybrid</name>
              <center>false</center>
            </submesh>
          </mesh>
        </geometry>
      </visual>

      <visual name="interior_visual">
        <geometry>
          <mesh>
            <uri>model://prius_hybrid/meshes/Hybrid.obj</uri>
            <scale>0.01 0.01 0.01</scale>
            <submesh>
              <name>Hybrid_Interior</name>
              <center>false</center>
            </submesh>
          </mesh>
        </geometry>
      </visual>

      <visual name="windows_visual">
        <geometry>
          <mesh>
            <uri>model://prius_hybrid/meshes/Hybrid.obj</uri>
            <scale>0.01 0.01 0.01</scale>
            <submesh>
              <name>Hybrid_Windows</name>
              <center>false</center>
            </submesh>
          </mesh>
        </geometry>
      </visual>

      <collision name="chassis">
        <pose>0.0 0.05 0.625 0 0 0</pose>
        <geometry>
          <box>
            <size>1.7526 2.1 0.95</size>
          </box>
        </geometry>
      </collision>

      <collision name="front_bumper">
        <pose>0.0 -2.0 0.458488 0.0 0 0</pose>
        <geometry>
          <box>
            <size>1.337282 0.48 0.566691</size>
          </box>
        </geometry>
      </collision>

      <collision name="hood">
        <pose>0.0 -1.900842 0.676305 0.341247 0 0</pose>
        <geometry>
          <box>
            <size>1.597968 0.493107 0.265468</size>
          </box>
        </geometry>
      </collision>

      <collision name="windshield">
        <pose>0.0 -0.875105 1.032268 0.335476 0 0</pose>
        <geometry>
          <box>
            <size>1.168381 1.654253 0.272347</size>
          </box>
        </geometry>
      </collision>

      <collision name="top_front">
        <pose>0.0 0.161236 1.386042 0.135030 0 0</pose>
        <geometry>
          <box>
            <size>1.279154 0.625988 0.171868</size>
          </box>
        </geometry>
      </collision>

      <collision name="top_rear">
        <pose>0.0 0.817696 1.360069 -0.068997 0 0</pose>
        <geometry>
          <box>
            <size>1.285130 0.771189 0.226557</size>
          </box>
        </geometry>
      </collision>

      <collision name="rear_window">
        <pose>0.0 1.640531 1.175126 -0.262017 0 0</pose>
        <geometry>
          <box>
            <size>1.267845 1.116344 0.244286</size>
          </box>
        </geometry>
      </collision>

      <collision name="trunk">
        <pose>0.0 1.637059 0.888180 0.0 0 0</pose>
        <geometry>
          <box>
            <size>1.788064 1.138988 0.482746</size>
          </box>
        </geometry>
      </collision>

      <collision name="back_bumper">
        <pose>0.0 2.054454 0.577870 0.0 0 0</pose>
        <geometry>
          <box>
            <size>1.781650 0.512093 0.581427</size>
          </box>
        </geometry>
      </collision>
   <sensor name='back_camera_sensor' type='camera'>
          <pose>0 1.45 1.3999999999999999 0 0.050000000000000003 1.5707</pose>
          <topic>back_camera</topic>
          <update_rate>30</update_rate>
          <enable_metrics>false</enable_metrics>
          <camera>
            <pose>0 0 0 0 0 0</pose>
            <horizontal_fov>1.3962600000000001</horizontal_fov>
            <image>
              <width>800</width>
              <height>800</height>
              <format>RGB_INT8</format>
              <anti_aliasing>4</anti_aliasing>
            </image>
            <camera_info_topic>__default__</camera_info_topic>
            <trigger_topic></trigger_topic>
            <triggered>false</triggered>
            <clip>
              <near>0.02</near>
              <far>300</far>
            </clip>
            <save enabled='false'>
              <path>__default__</path>
            </save>
            <visibility_mask>4294967295</visibility_mask>
            <noise>
              <type>none</type>
              <mean>0</mean>
              <stddev>0</stddev>
            </noise>
            <distortion>
              <k1>0</k1>
              <k2>0</k2>
              <k3>0</k3>
              <p1>0</p1>
              <p2>0</p2>
              <center>0.5 0.5</center>
            </distortion>
            <lens>
              <type>stereographic</type>
              <scale_to_hfov>true</scale_to_hfov>
              <cutoff_angle>1.5707963267948966</cutoff_angle>
              <env_texture_size>256</env_texture_size>
            </lens>
            <optical_frame_id></optical_frame_id>
          </camera>
        </sensor>
        <sensor name='front_camera_sensor' type='camera'>
          <pose>0 -0.40000000000000002 1.3999999999999999 0 0.050000000000000003 -1.5707</pose>
          <topic>front_camera</topic>
          <update_rate>30</update_rate>
          <enable_metrics>false</enable_metrics>
          <camera>
            <pose>0 0 0 0 0 0</pose>
            <horizontal_fov>1.3962600000000001</horizontal_fov>
            <image>
              <width>800</width>
              <height>800</height>
              <format>RGB_INT8</format>
              <anti_aliasing>4</anti_aliasing>
            </image>
            <camera_info_topic>__default__</camera_info_topic>
            <trigger_topic></trigger_topic>
            <triggered>false</triggered>
            <clip>
              <near>0.02</near>
              <far>300</far>
            </clip>
            <save enabled='false'>
              <path>__default__</path>
            </save>
            <visibility_mask>4294967295</visibility_mask>
            <noise>
              <type>none</type>
              <mean>0</mean>
              <stddev>0</stddev>
            </noise>
            <distortion>
              <k1>0</k1>
              <k2>0</k2>
              <k3>0</k3>
              <p1>0</p1>
              <p2>0</p2>
              <center>0.5 0.5</center>
            </distortion>
            <lens>
              <type>stereographic</type>
              <scale_to_hfov>true</scale_to_hfov>
              <cutoff_angle>1.5707963267948966</cutoff_angle>
              <env_texture_size>256</env_texture_size>
            </lens>
            <optical_frame_id></optical_frame_id>
          </camera>
        </sensor>
        <sensor name='left_camera_sensor' type='camera'>
          <pose>1 -0.69999999999999996 1 0 0.050000000000000003 1</pose>
          <topic>left_camera</topic>
          <update_rate>30</update_rate>
          <enable_metrics>false</enable_metrics>
          <camera>
            <pose>0 0 0 0 0 0</pose>
            <horizontal_fov>1.3962600000000001</horizontal_fov>
            <image>
              <width>800</width>
              <height>800</height>
              <format>RGB_INT8</format>
              <anti_aliasing>4</anti_aliasing>
            </image>
            <camera_info_topic>__default__</camera_info_topic>
            <trigger_topic></trigger_topic>
            <triggered>false</triggered>
            <clip>
              <near>0.02</near>
              <far>300</far>
            </clip>
            <save enabled='false'>
              <path>__default__</path>
            </save>
            <visibility_mask>4294967295</visibility_mask>
            <noise>
              <type>none</type>
              <mean>0</mean>
              <stddev>0</stddev>
            </noise>
            <distortion>
              <k1>0</k1>
              <k2>0</k2>
              <k3>0</k3>
              <p1>0</p1>
              <p2>0</p2>
              <center>0.5 0.5</center>
            </distortion>
            <lens>
              <type>stereographic</type>
              <scale_to_hfov>true</scale_to_hfov>
              <cutoff_angle>1.5707963267948966</cutoff_angle>
              <env_texture_size>256</env_texture_size>
            </lens>
            <optical_frame_id></optical_frame_id>
          </camera>
        </sensor>
        <sensor name='right_camera_sensor' type='camera'>
          <pose>-1 -0.69999999999999996 1 0 0.050000000000000003 2.1415999999999999</pose>
          <topic>right_camera</topic>
          <update_rate>30</update_rate>
          <enable_metrics>false</enable_metrics>
          <camera>
            <pose>0 0 0 0 0 0</pose>
            <horizontal_fov>1.3962600000000001</horizontal_fov>
            <image>
              <width>800</width>
              <height>800</height>
              <format>RGB_INT8</format>
              <anti_aliasing>4</anti_aliasing>
            </image>
            <camera_info_topic>__default__</camera_info_topic>
            <trigger_topic></trigger_topic>
            <triggered>false</triggered>
            <clip>
              <near>0.02</near>
              <far>300</far>
            </clip>
            <save enabled='false'>
              <path>__default__</path>
            </save>
            <visibility_mask>4294967295</visibility_mask>
            <noise>
              <type>none</type>
              <mean>0</mean>
              <stddev>0</stddev>
            </noise>
            <distortion>
              <k1>0</k1>
              <k2>0</k2>
              <k3>0</k3>
              <p1>0</p1>
              <p2>0</p2>
              <center>0.5 0.5</center>
            </distortion>
            <lens>
              <type>stereographic</type>
              <scale_to_hfov>true</scale_to_hfov>
              <cutoff_angle>1.5707963267948966</cutoff_angle>
              <env_texture_size>256</env_texture_size>
            </lens>
            <optical_frame_id></optical_frame_id>
          </camera>
          <plugin name='gz::sim::systems::Sensors' filename='gz-sim-sensors-system'>
            <render_engine>ogre2</render_engine>
          </plugin>
        </sensor>
        <pose>0 0 0 0 0 0</pose>
        <enable_wind>false</enable_wind>
      </link>
      <link name='steering_wheel'>
        <pose>0.35573105610193068 -0.62958652016180849 0.9872190620249981 -1.84043795307633 0.53747540387523196 -1.572477926540647</pose>
        <inertial>
          <mass>1</mass>
          <inertia>
            <ixx>0.14583299999999999</ixx>
            <ixy>0</ixy>
            <ixz>0</ixz>
            <iyy>0.14583299999999999</iyy>
            <iyz>0</iyz>
            <izz>0.125</izz>
          </inertia>
          <pose>0 0 0 0 0 0</pose>
        </inertial>
        <collision name='collision'>
          <geometry>
            <cylinder>
              <radius>0.178172</radius>
              <length>0.041845</length>
            </cylinder>
          </geometry>
          <surface>
            <contact>
              <ode>
                <min_depth>0.0030000000000000001</min_depth>
              </ode>
            </contact>
            <friction>
              <ode/>
            </friction>
            <bounce/>
          </surface>
        </collision>
        <visual name='visual'>
          <pose>0 0 0 1.302101 0 0</pose>
          <geometry>
            <mesh>
              <uri>model://prius_hybrid/meshes/Hybrid.obj</uri>
              <scale>0.01 0.01 0.01</scale>
              <submesh>
                <name>Steering_Wheel</name>
                <center>true</center>
              </submesh>
            </mesh>
          </geometry>
        </visual>
        <enable_wind>false</enable_wind>
      </link>
      <link name='front_left_wheel'>
        <pose>0.75999999846956712 -1.4100000143038756 0.29999999999999361 -1.0429080831108382 7.4887025626795096e-15 9.9338036410594557e-10</pose>
        <inertial>
          <mass>11</mass>
          <inertia>
            <ixx>0.58631237999999997</ixx>
            <ixy>0</ixy>
            <iyy>0.33552910000000002</iyy>
            <ixz>0</ixz>
            <iyz>0</iyz>
            <izz>0.33552910000000002</izz>
          </inertia>
          <pose>0 0 0 0 0 0</pose>
        </inertial>
        <visual name='visual'>
          <pose>0.040000000000000001 0 0 0 0 0</pose>
          <geometry>
            <mesh>
              <uri>model://prius_hybrid/meshes/Hybrid.obj</uri>
              <scale>0.01 0.01 0.01</scale>
              <submesh>
                <name>Wheel_Front_Left_</name>
                <center>true</center>
              </submesh>
            </mesh>
          </geometry>
        </visual>
        <collision name='collision'>
          <pose>0 0 0 0 1.5707963267948966 0</pose>
          <geometry>
            <sphere>
              <radius>0.31264999999999998</radius>
            </sphere>
          </geometry>
          <surface>
            <friction>
              <ode>
                <mu>0.90000000000000002</mu>
                <mu2>0.90000000000000002</mu2>
                <slip1>0</slip1>
                <slip2>0</slip2>
              </ode>
            </friction>
            <contact>
              <ode>
                <min_depth>0.001</min_depth>
                <kp>1000000000</kp>
              </ode>
            </contact>
            <bounce/>
          </surface>
        </collision>
        <enable_wind>false</enable_wind>
      </link>
      <link name='front_right_wheel'>
        <pose>-0.76000000655029964 -1.4100000611771861 0.30000000000000604 -1.0429080114250315 -1.9239291305763708e-15 9.7165275159306187e-10</pose>
        <inertial>
          <mass>11</mass>
          <inertia>
            <ixx>0.58631237999999997</ixx>
            <ixy>0</ixy>
            <iyy>0.33552910000000002</iyy>
            <ixz>0</ixz>
            <iyz>0</iyz>
            <izz>0.33552910000000002</izz>
          </inertia>
          <pose>0 0 0 0 0 0</pose>
        </inertial>
        <visual name='visual'>
          <pose>-0.040000000000000001 0 0 0 0 0</pose>
          <pose>0 0 0 0 0 0</pose>
          <geometry>
            <mesh>
              <uri>model://prius_hybrid/meshes/Hybrid.obj</uri>
              <scale>0.01 0.01 0.01</scale>
              <submesh>
                <name>Wheel_Front_Right</name>
                <center>true</center>
              </submesh>
            </mesh>
          </geometry>
        </visual>
        <collision name='collision'>
          <pose>0 0 0 0 1.5707963267948966 0</pose>
          <geometry>
            <sphere>
              <radius>0.31264999999999998</radius>
            </sphere>
          </geometry>
          <surface>
            <friction>
              <ode>
                <mu>0.90000000000000002</mu>
                <mu2>0.90000000000000002</mu2>
                <slip1>0</slip1>
                <slip2>0</slip2>
              </ode>
            </friction>
            <contact>
              <ode>
                <min_depth>0.001</min_depth>
                <kp>1000000000</kp>
              </ode>
            </contact>
            <bounce/>
          </surface>
        </collision>
        <enable_wind>false</enable_wind>
      </link>
      <link name='rear_left_wheel'>
        <pose>0.78600000000005821 1.4499999999998749 0.30000000007027694 -1.0429080710136502 -8.9411398558359047e-11 -8.1107455913584464e-17</pose>
        <inertial>
          <mass>11</mass>
          <inertia>
            <ixx>0.58631237999999997</ixx>
            <ixy>0</ixy>
            <iyy>0.33552910000000002</iyy>
            <ixz>0</ixz>
            <iyz>0</iyz>
            <izz>0.33552910000000002</izz>
          </inertia>
          <pose>0 0 0 0 0 0</pose>
        </inertial>
        <visual name='visual'>
          <pose>0.040000000000000001 0 0 0 0 0</pose>
          <geometry>
            <mesh>
              <uri>model://prius_hybrid/meshes/Hybrid.obj</uri>
              <scale>0.01 0.01 0.01</scale>
              <submesh>
                <name>Wheel_Front_Left_</name>
                <center>true</center>
              </submesh>
            </mesh>
          </geometry>
        </visual>
        <collision name='collision'>
          <pose>0 0 0 0 1.5707963267948966 0</pose>
          <geometry>
            <sphere>
              <radius>0.31264999999999998</radius>
            </sphere>
          </geometry>
          <surface>
            <friction>
              <ode>
                <mu>1.1000000000000001</mu>
                <mu2>1.1000000000000001</mu2>
                <slip1>0</slip1>
                <slip2>0</slip2>
              </ode>
            </friction>
            <contact>
              <ode>
                <min_depth>0.001</min_depth>
                <kp>1000000000</kp>
              </ode>
            </contact>
            <bounce/>
          </surface>
        </collision>
        <enable_wind>false</enable_wind>
      </link>
      <link name='rear_right_wheel'>
        <pose>-0.78599999999994452 1.4499999999999318 0.2999999999297227 -1.0429080097874193 -8.9411357596192733e-11 -2.3541639716914981e-16</pose>
        <inertial>
          <mass>11</mass>
          <inertia>
            <ixx>0.58631237999999997</ixx>
            <ixy>0</ixy>
            <iyy>0.33552910000000002</iyy>
            <ixz>0</ixz>
            <iyz>0</iyz>
            <izz>0.33552910000000002</izz>
          </inertia>
          <pose>0 0 0 0 0 0</pose>
        </inertial>
        <visual name='visual'>
          <pose>-0.040000000000000001 0 0 0 0 0</pose>
          <geometry>
            <mesh>
              <uri>model://prius_hybrid/meshes/Hybrid.obj</uri>
              <scale>0.01 0.01 0.01</scale>
              <submesh>
                <name>Wheel_Front_Right</name>
                <center>true</center>
              </submesh>
            </mesh>
          </geometry>
        </visual>
        <collision name='collision'>
          <pose>0 0 0 0 1.5707963267948966 0</pose>
          <geometry>
            <sphere>
              <radius>0.31264999999999998</radius>
            </sphere>
          </geometry>
          <surface>
            <friction>
              <ode>
                <mu>1.1000000000000001</mu>
                <mu2>1.1000000000000001</mu2>
                <slip1>0</slip1>
                <slip2>0</slip2>
              </ode>
            </friction>
            <contact>
              <ode>
                <min_depth>0.001</min_depth>
                <kp>1000000000</kp>
              </ode>
            </contact>
            <bounce/>
          </surface>
        </collision>
        <enable_wind>false</enable_wind>
      </link>
      <link name='rear_axle'>
        <pose>-1.4210854715202004e-14 1.4499999999999886 0.30000000000000071 2.6020852139652106e-18 -8.9410978620918513e-11 -1.1632749271782581e-28</pose>
        <inertial>
          <mass>30</mass>
          <inertia>
            <ixx>0.084374999999999992</ixx>
            <ixy>0</ixy>
            <iyy>4.64581</iyy>
            <ixz>0</ixz>
            <iyz>0</iyz>
            <izz>4.64581</izz>
          </inertia>
          <pose>0 0 0 0 0 0</pose>
        </inertial>
        <visual name='visual'>
          <pose>0 0 0 0 1.5707963267948966 0</pose>
          <geometry>
            <cylinder>
              <length>1.357</length>
              <radius>0.074999999999999997</radius>
            </cylinder>
          </geometry>
          <material>
            <script>
              <name>Gazebo/Grey</name>
              <uri>file://media/materials/scripts/gazebo.material</uri>
            </script>
          </material>
        </visual>
        <enable_wind>false</enable_wind>
      </link>
      <joint name='rear_axle_joint' type='revolute'>
        <child>rear_axle</child>
        <parent>chassis</parent>
        <axis>
          <xyz>0 1 0</xyz>
          <limit>
            <lower>-0.050890585241730277</lower>
            <upper>0.050890585241730277</upper>
            <effort>inf</effort>
            <velocity>inf</velocity>
            <stiffness>100000000</stiffness>
            <dissipation>1</dissipation>
          </limit>
          <dynamics>
            <spring_reference>0</spring_reference>
            <spring_stiffness>0</spring_stiffness>
            <damping>2000</damping>
            <friction>0</friction>
          </dynamics>
        </axis>
        <pose>0 0 0 0 0 0</pose>
      </joint>
      <joint name='rear_left_wheel_joint' type='revolute'>
        <child>rear_left_wheel</child>
        <parent>rear_axle</parent>
        <axis>
          <xyz>1 0 0</xyz>
          <limit>
            <lower>-inf</lower>
            <upper>inf</upper>
            <effort>inf</effort>
            <velocity>inf</velocity>
            <stiffness>100000000</stiffness>
            <dissipation>1</dissipation>
          </limit>
          <dynamics>
            <spring_reference>0</spring_reference>
            <spring_stiffness>0</spring_stiffness>
            <damping>0</damping>
            <friction>12.031606150200002</friction>
          </dynamics>
        </axis>
        <pose>0 0 0 0 0 0</pose>
      </joint>
      <joint name='rear_right_wheel_joint' type='revolute'>
        <child>rear_right_wheel</child>
        <parent>rear_axle</parent>
        <axis>
          <xyz>1 0 0</xyz>
          <limit>
            <lower>-inf</lower>
            <upper>inf</upper>
            <effort>inf</effort>
            <velocity>inf</velocity>
            <stiffness>100000000</stiffness>
            <dissipation>1</dissipation>
          </limit>
          <dynamics>
            <spring_reference>0</spring_reference>
            <spring_stiffness>0</spring_stiffness>
            <damping>0</damping>
            <friction>12.031606150200002</friction>
          </dynamics>
        </axis>
        <pose>0 0 0 0 0 0</pose>
      </joint>
      <joint name='steering_joint' type='revolute'>
        <pose>-0.002 -2.2204499999999999e-16 1.11022e-16 0 0 0</pose>
        <parent>chassis</parent>
        <child>steering_wheel</child>
        <axis>
          <xyz>0 0.96409540580664155 0.26555611177776933</xyz>
          <limit>
            <lower>-7.8499999999999996</lower>
            <upper>7.8499999999999996</upper>
            <effort>inf</effort>
            <velocity>inf</velocity>
            <stiffness>100000000</stiffness>
            <dissipation>1</dissipation>
          </limit>
          <dynamics>
            <spring_reference>0</spring_reference>
            <spring_stiffness>0</spring_stiffness>
            <damping>1</damping>
            <friction>0</friction>
          </dynamics>
        </axis>
        <physics>
          <ode>
            <cfm_damping>true</cfm_damping>
          </ode>
        </physics>
      </joint>
      <link name='front_left_wheel_steering_link'>
        <pose>0.75999999846956712 -1.4100000143038756 0.29999999999999361 1.6514567530433982e-15 7.8791140270663955e-15 9.9338015591143858e-10</pose>
        <inertial>
          <mass>0.5</mass>
          <inertia>
            <ixx>0.015299999999999999</ixx>
            <iyy>0.025000000000000001</iyy>
            <izz>0.015299999999999999</izz>
            <ixy>0</ixy>
            <ixz>0</ixz>
            <iyz>0</iyz>
          </inertia>
          <pose>0 0 0 0 0 0</pose>
        </inertial>
        <enable_wind>false</enable_wind>
      </link>
      <link name='front_right_wheel_steering_link'>
        <pose>-0.76000000655029964 -1.4100000611771861 0.30000000000000604 -2.922141696009403e-15 -1.4953316348723541e-15 9.7165286927491934e-10</pose>
        <inertial>
          <mass>0.5</mass>
          <inertia>
            <ixx>0.015299999999999999</ixx>
            <iyy>0.025000000000000001</iyy>
            <izz>0.015299999999999999</izz>
            <ixy>0</ixy>
            <ixz>0</ixz>
            <iyz>0</iyz>
          </inertia>
          <pose>0 0 0 0 0 0</pose>
        </inertial>
        <enable_wind>false</enable_wind>
      </link>
      <joint name='front_left_wheel_steering_joint' type='revolute'>
        <child>front_left_wheel_steering_link</child>
        <parent>chassis</parent>
        <axis>
          <xyz>0 0 1</xyz>
          <limit>
            <lower>-0.87270000000000003</lower>
            <upper>0.87270000000000003</upper>
            <effort>1000000</effort>
            <velocity>inf</velocity>
            <stiffness>100000000</stiffness>
            <dissipation>1</dissipation>
          </limit>
          <dynamics>
            <spring_reference>0</spring_reference>
            <spring_stiffness>0</spring_stiffness>
            <damping>0</damping>
            <friction>0</friction>
          </dynamics>
        </axis>
        <pose>0 0 0 0 0 0</pose>
      </joint>
      <joint name='front_right_wheel_steering_joint' type='revolute'>
        <parent>chassis</parent>
        <child>front_right_wheel_steering_link</child>
        <axis>
          <xyz>0 0 1</xyz>
          <limit>
            <lower>-0.87270000000000003</lower>
            <upper>0.87270000000000003</upper>
            <effort>1000000</effort>
            <velocity>inf</velocity>
            <stiffness>100000000</stiffness>
            <dissipation>1</dissipation>
          </limit>
          <dynamics>
            <spring_reference>0</spring_reference>
            <spring_stiffness>0</spring_stiffness>
            <damping>0</damping>
            <friction>0</friction>
          </dynamics>
        </axis>
        <pose>0 0 0 0 0 0</pose>
      </joint>
      <joint name='front_left_wheel_joint' type='revolute'>
        <parent>front_left_wheel_steering_link</parent>
        <child>front_left_wheel</child>
        <axis>
          <xyz>1 0 0</xyz>
          <limit>
            <lower>-1.7976900000000001e+308</lower>
            <upper>1.7976900000000001e+308</upper>
            <effort>inf</effort>
            <velocity>inf</velocity>
            <stiffness>100000000</stiffness>
            <dissipation>1</dissipation>
          </limit>
          <dynamics>
            <spring_reference>0</spring_reference>
            <spring_stiffness>0</spring_stiffness>
            <damping>0</damping>
            <friction>18.047409225300001</friction>
          </dynamics>
        </axis>
        <pose>0 0 0 0 0 0</pose>
      </joint>
      <joint name='front_right_wheel_joint' type='revolute'>
        <parent>front_right_wheel_steering_link</parent>
        <child>front_right_wheel</child>
        <axis>
          <xyz>1 0 0</xyz>
          <limit>
            <lower>-1.7976900000000001e+308</lower>
            <upper>1.7976900000000001e+308</upper>
            <effort>inf</effort>
            <velocity>inf</velocity>
            <stiffness>100000000</stiffness>
            <dissipation>1</dissipation>
          </limit>
          <dynamics>
            <spring_reference>0</spring_reference>
            <spring_stiffness>0</spring_stiffness>
            <damping>0</damping>
            <friction>18.047409225300001</friction>
          </dynamics>
        </axis>
        <pose>0 0 0 0 0 0</pose>
      </joint>
      <plugin name='gz::sim::systems::AckermannSteering' filename='gz-sim-ackermann-steering-system'>
        <topic>/cmd_vel</topic>
        <!-- <left_joint>front_left_wheel_joint</left_joint> -->
        <left_joint>rear_left_wheel_joint</left_joint>
        <!-- <right_joint>front_right_wheel_joint</right_joint> -->
        <right_joint>rear_right_wheel_joint</right_joint>
        <left_steering_joint>front_left_wheel_steering_joint</left_steering_joint>
        <right_steering_joint>front_right_wheel_steering_joint</right_steering_joint>
        <kingpin_width>1.530</kingpin_width>
        <steering_limit>0.5</steering_limit>
        <wheel_base>2.7</wheel_base>
        <wheel_separation>1.572</wheel_separation>
        <wheel_radius>0.31265</wheel_radius>
        <min_velocity>-10</min_velocity>
        <max_velocity>100</max_velocity>
        <min_acceleration>-30</min_acceleration>
        <max_acceleration>30</max_acceleration>
        
      </plugin>
      <plugin filename="gz-sim-joint-state-publisher-system" name="gz::sim::systems::JointStatePublisher">
        <joint_name>front_left_wheel_joint</joint_name>
        <joint_name>front_right_wheel_joint</joint_name>
        <joint_name>rear_left_wheel_joint</joint_name>
        <joint_name>rear_right_wheel_joint</joint_name>
        <joint_name>front_left_wheel_steering_joint</joint_name>
        <joint_name>front_right_wheel_steering_joint</joint_name>
      </plugin>
      <static>false</static>
      <self_collide>false</self_collide>
  </model>

</sdf>
